<mujoco model="arx5">
  <actuator>
    <!-- Physical limits of the actuator. Pulled from raw actuator spec sheet, see:
      https://www.kinovarobotics.com/sites/default/files/AS-ACT-KA58-KA75-SP-INT-EN%20201804-1.2%20%28KINOVA%E2%84%A2%20Actuator%20series%20KA75%2B%20KA-58%20Specifications%29.pdf -->
    <motor ctrllimited="true" ctrlrange="-100 100" joint="joint1" name="torq_j1"/>
    <motor ctrllimited="true" ctrlrange="-100 100" joint="joint2" name="torq_j2"/>
    <motor ctrllimited="true" ctrlrange="-100 100" joint="joint3" name="torq_j3"/>
    <motor ctrllimited="true" ctrlrange="-100 100" joint="joint4" name="torq_j4"/>
    <motor ctrllimited="true" ctrlrange="-100 100" joint="joint5" name="torq_j5"/>
    <motor ctrllimited="true" ctrlrange="-100 100" joint="joint6" name="torq_j6"/>
   
  </actuator>
  <asset>
    <mesh name="base_link" file="meshes/base_link.STL"/>
    <mesh name="link1" file="meshes/link1.STL"/>
    <mesh name="link2" file="meshes/link2.STL"/>
    <mesh name="link3" file="meshes/link3.STL"/>
    <mesh name="link4" file="meshes/link4.STL"/>
    <mesh name="link5" file="meshes/link5.STL"/>
    <mesh name="link6" file="meshes/link6.STL"/>

  
  </asset>
  <worldbody>
    <body name="base" pos="0 0 0">
      <!-- robot view -->
      <camera mode="fixed" name="robotview" pos="1.0 0 0.4" quat="0.653 0.271 0.271 0.653"/>
    
      <!-- mount attached here -->
      <body name="base_link" pos="0 0 0">
        <inertial diaginertia="0 0 0" mass="0" pos="0 0 0"/>
        <geom type="mesh" contype="0" conaffinity="0" group="1" density="0" rgba="0.752941 0.752941 0.752941 1" mesh="base_link"/>
        <geom type="mesh" rgba="0.752941 0.752941 0.752941 1" mesh="base_link"/>
        <body name="link1" pos="0 0 0.0635">
          <inertial pos="0.0059384 -0.004726 0.0175081" quat="0.552568 0.725987 -0.305979 0.272009" mass="0.0601565" diaginertia="8.10278e-05 6.14637e-05 2.75086e-05"/>
          <joint name="joint1" pos="0 0 0" axis="0 0 1" range="-360 360"/>
          <geom type="mesh" contype="0" conaffinity="0" group="1" density="0" rgba="0.752941 0.752941 0.752941 1" mesh="link1"/>
          <geom type="mesh" rgba="0.752941 0.752941 0.752941 1" mesh="link1"/>
          <body name="link2" pos="0.02 0 0.04">
            <inertial pos="-0.133119 0.00212876 0.000300079" quat="0 0.705747 0 0.708464" mass="1.085" diaginertia="0.0161302 0.01608 0.00050977"/>
            <joint name="joint2" pos="0 0 0" axis="0 1 0" range="-360 360"/>
            <geom type="mesh" contype="0" conaffinity="0" group="1" density="0" rgba="0.752941 0.752941 0.752941 1" mesh="link2"/>
            <geom type="mesh" rgba="0.752941 0.752941 0.752941 1" mesh="link2"/>
            <body name="link3" pos="-0.264 0 0" quat="-3.67321e-06 1 0 0">
              <inertial pos="0.187211 -0.000291649 -0.0515193" quat="0.223666 0.632665 0.21268 0.710264" mass="0.503071" diaginertia="0.00389555 0.00385857 0.00028588"/>
              <joint name="joint3" pos="0 0 0" axis="0 1 0" range="-360 360"/>
              <geom type="mesh" contype="0" conaffinity="0" group="1" density="0" rgba="0.752941 0.752941 0.752941 1" mesh="link3"/>
              <geom type="mesh" rgba="0.752941 0.752941 0.752941 1" mesh="link3"/>
              <body name="link4" pos="0.245 0 -0.056">
                <inertial pos="0.0371664 0.00481376 -0.0314687" quat="0.925169 -0.0632912 0.294705 -0.230662" mass="0.0973571" diaginertia="0.000216632 0.000182744 6.06242e-05"/>
                <joint name="joint4" pos="0 0 0" axis="0 1 0" range="-360 360"/>
                <geom type="mesh" contype="0" conaffinity="0" group="1" density="0" rgba="0.898039 0.917647 0.929412 1" mesh="link4"/>
                <geom type="mesh" rgba="0.898039 0.917647 0.929412 1" mesh="link4"/>
                <body name="link5" pos="0.06675 0 -0.084">
                  <inertial pos="0.00304994 -4.95382e-05 0.0540299" quat="0.998829 0 -0.0483866 0" mass="0.596991" diaginertia="0.000724856 0.0007 0.000205144"/>
                  <joint name="joint5" pos="0 0 0" axis="0 0 1" range="-360 360"/>
                  <geom type="mesh" contype="0" conaffinity="0" group="1" density="0" rgba="0.752941 0.752941 0.752941 1" mesh="link5"/>
                  <geom type="mesh" rgba="0.752941 0.752941 0.752941 1" mesh="link5"/>
                  <body name="link6" pos="0.03045 0 0.084" quat="-3.67321e-06 -1 0 0">
                    <inertial pos="0.0365156 -1.47703e-05 0.000265587" quat="0.5 0.5 -0.5 0.5" mass="0.315932" diaginertia="0.00038 0.00031 0.00015"/>
                    <joint name="joint6" pos="0 0 0" axis="1 0 0" range="-360 360"/>
                    <body name="right_hand" pos="0 0 0">
                      <!-- This sites were added for visualization. They are all standardized between models-->
                      <!-- Position mimics the gripper attachment point (right_hand) -->
                      <!--  Y-axis should be perpendicular to grasping motion, and Z-axis should point out of the robot eef -->
                      <site name="ee" pos="0 0 0" size="0.01 0.01 0.01" rgba="0 0 1 1" type="sphere" group="1"/>
                      <site name="ee_x" pos="0 0 0" size="0.005 .1"  quat="0.707105 0.707108 0 0 " rgba="1 0 0 0" type="cylinder" group="1"/>
                      <site name="ee_z" pos="0 0 0" size="0.005 .1" quat="0.707105 0 0 0.707108" rgba="0 0 1 0" type="cylinder" group="1"/>
                      <site name="ee_y" pos="0 0 0" size="0.005 .1" quat="0.707105 0 0.707108 0 " rgba="0 1 0 0" type="cylinder" group="1"/>
                      <!-- This camera points out from the eef. -->
                      <camera mode="fixed" name="eye_in_hand" pos="0.05 0 0" quat="0 0.707108 0.707108 0" fovy="75"/>
                      <!-- to add gripper -->
                    </body>
                    
                  </body>
                </body>
              </body>
            </body>
          </body>
        </body>
      </body>
    </body>
  </worldbody>
</mujoco>
