<mujoco model="Arx5G">

  <asset>
    <mesh name="base_link" file="meshes/Arx5_gripper/base_link.STL"/>
    <mesh name="link1" file="meshes/Arx5_gripper/link1.STL"/>
    <mesh name="link2" file="meshes/Arx5_gripper/link2.STL"/>
  </asset>
  <actuator>
    <position ctrllimited="true" ctrlrange="0 0.04765" joint="joint1" kp="1000" name="gripper_finger_joint1" forcelimited="true" forcerange="-1000 1000"/>
    <position ctrllimited="true" ctrlrange="-0.1765 0" joint="joint2" kp="1000" name="gripper_finger_joint2" forcelimited="true" forcerange="-3000 3000"/>
  </actuator>
  <worldbody>
    <body name="right_gripper" pos="0 0 0">
      <site name="ft_frame" pos="0 0 0" size="0.01 0.01 0.01" rgba="1 0 0 1" type="sphere" group="1" />
      <geom type="mesh" contype="0" conaffinity="0" group="1" density="0" rgba="0.89804 0.91765 0.92941 1" mesh="base_link"/>
      <geom type="mesh" rgba="0.89804 0.91765 0.92941 1" mesh="base_link"/>
      <body name="eef" pos="0 0 0.097" quat="0.1 0 0.1 0">
        <site name="grip_site" pos="0.1 0 0.135" size="0.01 0.01 0.01" rgba="1 0 0 0.5" type="sphere" group="1"/>
        <site name="ee_x" pos="0.1 0 0" size="0.005 .1"  quat="0.707105  0 0.707108 0 " rgba="1 0 0 0" type="cylinder" group="1"/>
        <site name="ee_y" pos="0 0.1 0" size="0.005 .1" quat="0.707105 0.707108 0 0" rgba="0 1 0 0" type="cylinder" group="1"/>
        <site name="ee_z" pos="0 0.1 0" size="0.005 .1" quat="1 0 0 0" rgba="0 0 1 0" type="cylinder" group="1"/>
        <!-- This site was added for visualization. -->
        <site name="grip_site_cylinder" pos="0.1 0 0.1" size="0.005 10" rgba="0 1 0 0.3" type="cylinder" group="1"/>
      </body>
      <body name="link1" pos="0.073574 0.024629 0">
        <inertial pos="-0.000327643 -0.00482005 -0.00167541" quat="0.5 0.5 0.5 0.5" mass="0.0484017" diaginertia="2e-05 2e-05 1e-05"/>
        <joint name="joint1" pos="0 0 0" axis="0 1 0" type="slide" range="0 0.04765"/>
        <geom type="mesh" contype="0" conaffinity="0" group="1" density="0" rgba="0.898039 0.917647 0.929412 1" mesh="link1"/>
        <geom type="mesh" rgba="0.898039 0.917647 0.929412 1" mesh="link1"/>
        <body name="finger_joint1_tip" pos="0.05 -0.015 0.005">
                    <inertial pos="0 0 0" quat="0 0 0 1" mass="0.01" diaginertia="0.01 0.01 0.01" />
                    <geom size="0.025 0.004 0.008" pos="0 -0.005 -0.015"  quat="0 0 0 1" type="box" group="0" solref="0.01 0.5" friction = "2 0.05 0.0001" conaffinity="1" contype="1" name="finger1_pad_collision"/>
        </body>
      </body>
      <body name="link2" pos="0.073574 -0.024629 0">
        <inertial pos="-0.000327644 0.00482005 0.000752973" quat="0.5 0.5 0.5 0.5" mass="0.0484017" diaginertia="2e-05 2e-05 1e-05"/>
        <joint name="joint2" pos="0 0 0" axis="0 1 0" type="slide" range="0 0.04765"/>
        <geom type="mesh" contype="0" conaffinity="0" group="1" density="0" rgba="0.898039 0.917647 0.929412 1" mesh="link2"/>
        <geom type="mesh" rgba="0.898039 0.917647 0.929412 1" mesh="link2"/>
        <body name="finger_joint2_tip" pos="0.05 0.015 0.005">
                    <inertial pos="0 0 0" quat="0 0 0 1" mass="0.01" diaginertia="0.01 0.01 0.01" />
                    <geom size="0.025 0.004 0.008" pos="0 0.005 -0.015" quat="0 0 0 1" type="box" group="0" solref="0.01 0.5" friction = "2 0.05 0.0001" conaffinity="1" contype="1" name="finger2_pad_collision"/>
        </body>
      </body>
    </body>
  </worldbody>
  <sensor>
        <force name="force_ee" site="ft_frame"/>
        <torque name="torque_ee" site="ft_frame"/>
  </sensor>

</mujoco>
